nohup: ignoring input
Not using data augmentation
Checkpoint not found, will create a new one: ./CGAN/checkpoints/baseline_CGAN_g_0.001_d_0.001_0.1_512_1024.pth
Trainable parameters: 13602373
Non-trainable parameters: 0.0
Total parameters: 13602373.0
> /user/sbove/Dottorato/Generative_AI/CGAN/GAN.py(128)train_one_epoch()
-> x_true=x_true.to(self.device)
(Pdb) Traceback (most recent call last):
  File "/user/sbove/Dottorato/Generative_AI/train.py", line 54, in <module>
    model.training_epoch(checkpoint_path, training_loader)
  File "/user/sbove/Dottorato/Generative_AI/CGAN/GAN.py", line 97, in training_epoch
    loss_generator, loss_discriminator, sum_dtrue, sum_dsynth = self.train_one_epoch(dataloader)
                                                                ^^^^^^^^^^^^^^^^^^^^^^^^^^^^^^^^
  File "/user/sbove/Dottorato/Generative_AI/CGAN/GAN.py", line 128, in train_one_epoch
    x_true=x_true.to(self.device)
           ^^^^^^
  File "/user/sbove/anaconda3/envs/ICareMeEnv/lib/python3.12/bdb.py", line 90, in trace_dispatch
    return self.dispatch_line(frame)
           ^^^^^^^^^^^^^^^^^^^^^^^^^
  File "/user/sbove/anaconda3/envs/ICareMeEnv/lib/python3.12/bdb.py", line 114, in dispatch_line
    self.user_line(frame)
  File "/user/sbove/anaconda3/envs/ICareMeEnv/lib/python3.12/pdb.py", line 341, in user_line
    self.interaction(frame, None)
  File "/user/sbove/anaconda3/envs/ICareMeEnv/lib/python3.12/pdb.py", line 439, in interaction
    self._cmdloop()
  File "/user/sbove/anaconda3/envs/ICareMeEnv/lib/python3.12/pdb.py", line 402, in _cmdloop
    self.cmdloop()
  File "/user/sbove/anaconda3/envs/ICareMeEnv/lib/python3.12/cmd.py", line 126, in cmdloop
    line = input(self.prompt)
           ^^^^^^^^^^^^^^^^^^
OSError: [Errno 9] Bad file descriptor
